#!/usr/bin/env python3
# -*- coding: utf-8 -*-
# 高级语言通常都内置了一套try...except...finally...的错误处理机制，Python也不例外。

try:
    print('try...')
    r = 10 / 0
    print('result:', r)
except ZeroDivisionError as e:
    print('except:', e)
finally:
    print('finally...')
print('END')

# Python的错误其实也是class，所有的错误类型都继承自BaseException，所以在使用except时需要注意的是，它不但捕获该类型的错误，还把其子类也“一网打尽”。比如：

# try:
#     foo()
# except ValueError as e:
#     print('ValueError')
# except UnicodeError as e:
#     print('UnicodeError')
# 第二个except永远也捕获不到UnicodeError，因为UnicodeError是ValueError的子类，如果有，也被第一个except给捕获了。

# Python所有的错误都是从BaseException类派生的，常见的错误类型和继承关系看这里：

# https://docs.python.org/3/library/exceptions.html#exception-hierarchy

# 使用try...except捕获错误还有一个巨大的好处，就是可以跨越多层调用，比如函数main()调用bar()，bar()调用foo()，结果foo()出错了，这时，只要main()捕获到了，就可以处理：

# def foo(s):
#     return 10 / int(s)

# def bar(s):
#     return foo(s) * 2

# def main():
#     try:
#         bar('0')
#     except Exception as e:
#         print('Error:', e)
#     finally:
#         print('finally...')
# 也就是说，不需要在每个可能出错的地方去捕获错误，只要在合适的层次去捕获错误就可以了。这样一来，就大大减少了写try...except...finally的麻烦。

# 练习
# 运行下面的代码，根据异常信息进行分析，定位出错误源头，并修复：
from functools import reduce

def str2num(s):
    try:
        return int(s)
    except Exception as e:
        print('Error:', e)
        return float(s)

def calc(exp):
    ss = exp.split('+')
    ns = map(str2num, ss)
    return reduce(lambda acc, x: acc + x, ns)

def main():
    r = calc('100 + 200 + 345')
    print('100 + 200 + 345 =', r)
    r = calc('99 + 88 + 7.6')
    print('99 + 88 + 7.6 =', r)

main()

# 调试
# 断言
# 凡是用print()来辅助查看的地方，都可以用断言（assert）来替代：

# def foo(s):
#     n = int(s)
#     assert n != 0, 'n is zero!'
#     return 10 / n

# def main():
#     foo('0')

# logging
# pdb

